Workbook
Name SlicerCache_Table_1_Col_3: #N/A

Sheet Documentation
A1: Project Title: Multi-Vendor Logistics SLA & Revenue Leakage Engine
A2: Objective: Identify 3PL delivery SLA breaches, isolate delayed carriers, and calculate contractual financial penalty claims
A3: Data Size: 1,000 transaction records

Sheet Raw_Data
A1: Tracking_ID | B1: Vendor_Name | C1: Destination_Zone | D1: Dispatch_Date | E1: Delivery_Date | F1: Order_Value_INR
A2: TRK100000 | B2: EcomExpress | C2: Tier 3 | D2: 46058 | E2: 46064 | F2: 8482
A3: TRK100001 | B3: Delhivery | C3: Tier 2 | D3: 46068 | E3: 46075 | F3: 4607
A4: TRK100002 | B4: Delhivery | C4: Metro | D4: 46077 | E4: 46080 | F4: 1841
A5: TRK100003 | B5: EcomExpress | C5: Tier 3 | D5: 46041 | E5: 46047 | F5: 8907
A6: TRK100004 | B6: BlueDart | C6: Metro | D6: 46071 | E6: 46073 | F6: 838
A7: TRK100005 | B7: Delhivery | C7: Tier 2 | D7: 46040 | E7: 46044 | F7: 6395
A8: TRK100006 | B8: Delhivery | C8: Tier 3 | D8: 46080 | E8: 46086 | F8: 3208
A9: TRK100007 | B9: Delhivery | C9: Tier 3 | D9: 46032 | E9: 46040 | F9: 11844
A10: TRK100008 | B10: EcomExpress | C10: Tier 3 | D10: 46028 | E10: 46034 | F10: 2250
A11: TRK100009 | B11: Delhivery | C11: Metro | D11: 46075 | E11: 46078 | F11: 6104
A12: TRK100010 | B12: EcomExpress | C12: Tier 2 | D12: 46079 | E12: 46083 | F12: 2921
A13: TRK100011 | B13: EcomExpress | C13: Metro | D13: 46082 | E13: 46087 | F13: 7619
... A20: TRK100018 | B20: Delhivery | C20: Metro | D20: 46082 | E20: 46084 | F20: 8544
A21: TRK100019 | B21: Delhivery | C21: Metro | D21: 46076 | F21: 8738
A22: TRK100020 | B22: Delhivery | C22: Metro | D22: 46064 | E22: 46066 | F22: 5373
A23: TRK100021 | B23: EcomExpress | C23: Tier 2 | D23: 46073 | E23: 46077 | F23: 5306
A24: TRK100022 | B24: EcomExpress | C24: Tier 3 | D24: 46031 | E24: 46037 | F24: 9092
A25: TRK100023 | B25: Delhivery | C25: Tier 3 | D25: 46041 | E25: 46047 | F25: 6413
A26: TRK100024 | B26: EcomExpress | C26: Tier 3 | D26: 46067 | E26: 46073 | F26: 7624
A27: TRK100025 | B27: Delhivery | C27: Tier 2 | D27: 46071 | E27: 46076 | F27: 3657
A28: TRK100026 | B28: EcomExpress | C28: Tier 2 | D28: 46053 | E28: 46057 | F28: 890
A29: TRK100027 | B29: EcomExpress | C29: Metro | D29: 46062 | E29: 46064 | F29: 4930
A30: TRK100028 | B30: EcomExpress | C30: Tier 2 | D30: 46080 | E30: 46084 | F30: 9320
A31: TRK100029 | B31: EcomExpress | C31: Tier 3 | D31: 46024 | E31: 46030 | F31: 8186
A32: TRK100030 | B32: BlueDart | C32: Tier 2 | D32: 46036 | E32: 46040 | F32: 4732
A33: TRK100031 | B33: Delhivery | C33: Tier 3 | D33: 46058 | E33: 46064 | F33: 11622
... A45: TRK100043 | B45: BlueDart | C45: Tier 2 | D45: 46024 | E45: 46030 | F45: 1966
A46: TRK100044 | B46: Delhivery | C46: Tier 3 | D46: 46055 | F46: 4061
A47: TRK100045 | B47: Delhivery | C47: Tier 2 | D47: 46038 | E47: 46042 | F47: 1114
A48: TRK100046 | B48: BlueDart | C48: Metro | D48: 46032 | E48: 46034 | F48: 5892
A49: TRK100047 | B49: Delhivery | C49: Metro | D49: 46050 | E49: 46052 | F49: 8193
A50: TRK100048 | B50: BlueDart | C50: Metro | D50: 46062 | E50: 46064 | F50: 9874
A51: TRK100049 | B51: BlueDart | C51: Tier 3 | D51: 46038 | E51: 46044 | F51: 3723
A52: TRK100050 | B52: EcomExpress | C52: Tier 3 | D52: 46049 | E52: 46058 | F52: 7638
A53: TRK100051 | B53: BlueDart | C53: Tier 3 | D53: 46065 | E53: 46072 | F53: 3167
A54: TRK100052 | B54: Delhivery | C54: Metro | D54: 46028 | E54: 46033 | F54: 8480
A55: TRK100053 | B55: EcomExpress | C55: Tier 3 | D55: 46046 | E55: 46054 | F55: 630
A56: TRK100054 | B56: BlueDart | C56: Tier 2 | D56: 46056 | E56: 46060 | F56: 3483
A57: TRK100055 | B57: EcomExpress | C57: Tier 3 | D57: 46055 | E57: 46064 | F57: 4778
...

Sheet Cleaned_Data
A1: Tracking_ID | B1: Vendor_Name | C1: Destination_Zone | D1: Dispatch_Date | E1: Delivery_Date | F1: Target_SLA_Days | G1: Actual_Business_Days | H1: SLA_Status | I1: Order_Value_INR | J1: Penalty_Claim_INR
A2: =Raw_Data!A2 -> TRK100000 | B2: =TRIM(Raw_Data!B2) -> EcomExpress | C2: =TRIM(Raw_Data!C2) -> Tier 3 | D2: =DATEVALUE(TEXT(Raw_Data!D2, "YYYY-MM-DD")) -> 46058 | E2: =IF(ISBLANK(Raw_Data!E2), "", DATEVALUE(TEXT(Raw_Data!E2, "YYYY-MM-DD"))) -> 46064 | F2: =IF(C2="Metro", 2, IF(C2="Tier 2", 4, 6)) -> 6 | G2: =IF(E2="", "In-Transit", NETWORKDAYS(D2, E2)) -> 5 | H2: =IF(G2="In-Transit", "Pending", IF(G2>F2, "SLA BREACH", "ON TIME")) -> ON TIME | I2: =Raw_Data!F2 -> 8482 | J2: =IF(H2="SLA BREACH", I2 * 0.05, 0) -> 0
A3: =Raw_Data!A3 -> TRK100001 | B3: =TRIM(Raw_Data!B3) -> Delhivery | C3: =TRIM(Raw_Data!C3) -> Tier 2 | D3: =DATEVALUE(TEXT(Raw_Data!D3, "YYYY-MM-DD")) -> 46068 | E3: =IF(ISBLANK(Raw_Data!E3), "", DATEVALUE(TEXT(Raw_Data!E3, "YYYY-MM-DD"))) -> 46075 | F3: =IF(C3="Metro", 2, IF(C3="Tier 2", 4, 6)) -> 4 | G3: =IF(E3="", "In-Transit", NETWORKDAYS(D3, E3)) -> 5 | H3: =IF(G3="In-Transit", "Pending", IF(G3>F3, "SLA BREACH", "ON TIME")) -> SLA BREACH | I3: =Raw_Data!F3 -> 4607 | J3: =IF(H3="SLA BREACH", I3 * 0.05, 0) -> 230.35
A4: =Raw_Data!A4 -> TRK100002 | B4: =TRIM(Raw_Data!B4) -> Delhivery | C4: =TRIM(Raw_Data!C4) -> Metro | D4: =DATEVALUE(TEXT(Raw_Data!D4, "YYYY-MM-DD")) -> 46077 | E4: =IF(ISBLANK(Raw_Data!E4), "", DATEVALUE(TEXT(Raw_Data!E4, "YYYY-MM-DD"))) -> 46080 | F4: =IF(C4="Metro", 2, IF(C4="Tier 2", 4, 6)) -> 2 | G4: =IF(E4="", "In-Transit", NETWORKDAYS(D4, E4)) -> 4 | H4: =IF(G4="In-Transit", "Pending", IF(G4>F4, "SLA BREACH", "ON TIME")) -> SLA BREACH | I4: =Raw_Data!F4 -> 1841 | J4: =IF(H4="SLA BREACH", I4 * 0.05, 0) -> 92.05
A5: =Raw_Data!A5 -> TRK100003 | B5: =TRIM(Raw_Data!B5) -> EcomExpress | C5: =TRIM(Raw_Data!C5) -> Tier 3 | D5: =DATEVALUE(TEXT(Raw_Data!D5, "YYYY-MM-DD")) -> 46041 | E5: =IF(ISBLANK(Raw_Data!E5), "", DATEVALUE(TEXT(Raw_Data!E5, "YYYY-MM-DD"))) -> 46047 | F5: =IF(C5="Metro", 2, IF(C5="Tier 2", 4, 6)) -> 6 | G5: =IF(E5="", "In-Transit", NETWORKDAYS(D5, E5)) -> 5 | H5: =IF(G5="In-Transit", "Pending", IF(G5>F5, "SLA BREACH", "ON TIME")) -> ON TIME | I5: =Raw_Data!F5 -> 8907 | J5: =IF(H5="SLA BREACH", I5 * 0.05, 0) -> 0
A6: =Raw_Data!A6 -> TRK100004 | B6: =TRIM(Raw_Data!B6) -> BlueDart | C6: =TRIM(Raw_Data!C6) -> Metro | D6: =DATEVALUE(TEXT(Raw_Data!D6, "YYYY-MM-DD")) -> 46071 | E6: =IF(ISBLANK(Raw_Data!E6), "", DATEVALUE(TEXT(Raw_Data!E6, "YYYY-MM-DD"))) -> 46073 | F6: =IF(C6="Metro", 2, IF(C6="Tier 2", 4, 6)) -> 2 | G6: =IF(E6="", "In-Transit", NETWORKDAYS(D6, E6)) -> 3 | H6: =IF(G6="In-Transit", "Pending", IF(G6>F6, "SLA BREACH", "ON TIME")) -> SLA BREACH | I6: =Raw_Data!F6 -> 838 | J6: =IF(H6="SLA BREACH", I6 * 0.05, 0) -> 41.9
A7: =Raw_Data!A7 -> TRK100005 | B7: =TRIM(Raw_Data!B7) -> Delhivery | C7: =TRIM(Raw_Data!C7) -> Tier 2 | D7: =DATEVALUE(TEXT(Raw_Data!D7, "YYYY-MM-DD")) -> 46040 | E7: =IF(ISBLANK(Raw_Data!E7), "", DATEVALUE(TEXT(Raw_Data!E7, "YYYY-MM-DD"))) -> 46044 | F7: =IF(C7="Metro", 2, IF(C7="Tier 2", 4, 6)) -> 4 | G7: =IF(E7="", "In-Transit", NETWORKDAYS(D7, E7)) -> 4 | H7: =IF(G7="In-Transit", "Pending", IF(G7>F7, "SLA BREACH", "ON TIME")) -> ON TIME | I7: =Raw_Data!F7 -> 6395 | J7: =IF(H7="SLA BREACH", I7 * 0.05, 0) -> 0
A8: =Raw_Data!A8 -> TRK100006 | B8: =TRIM(Raw_Data!B8) -> Delhivery | C8: =TRIM(Raw_Data!C8) -> Tier 3 | D8: =DATEVALUE(TEXT(Raw_Data!D8, "YYYY-MM-DD")) -> 46080 | E8: =IF(ISBLANK(Raw_Data!E8), "", DATEVALUE(TEXT(Raw_Data!E8, "YYYY-MM-DD"))) -> 46086 | F8: =IF(C8="Metro", 2, IF(C8="Tier 2", 4, 6)) -> 6 | G8: =IF(E8="", "In-Transit", NETWORKDAYS(D8, E8)) -> 5 | H8: =IF(G8="In-Transit", "Pending", IF(G8>F8, "SLA BREACH", "ON TIME")) -> ON TIME | I8: =Raw_Data!F8 -> 3208 | J8: =IF(H8="SLA BREACH", I8 * 0.05, 0) -> 0
A9: =Raw_Data!A9 -> TRK100007 | B9: =TRIM(Raw_Data!B9) -> Delhivery | C9: =TRIM(Raw_Data!C9) -> Tier 3 | D9: =DATEVALUE(TEXT(Raw_Data!D9, "YYYY-MM-DD")) -> 46032 | E9: =IF(ISBLANK(Raw_Data!E9), "", DATEVALUE(TEXT(Raw_Data!E9, "YYYY-MM-DD"))) -> 46040 | F9: =IF(C9="Metro", 2, IF(C9="Tier 2", 4, 6)) -> 6 | G9: =IF(E9="", "In-Transit", NETWORKDAYS(D9, E9)) -> 5 | H9: =IF(G9="In-Transit", "Pending", IF(G9>F9, "SLA BREACH", "ON TIME")) -> ON TIME | I9: =Raw_Data!F9 -> 11844 | J9: =IF(H9="SLA BREACH", I9 * 0.05, 0) -> 0
A10: =Raw_Data!A10 -> TRK100008 | B10: =TRIM(Raw_Data!B10) -> EcomExpress | C10: =TRIM(Raw_Data!C10) -> Tier 3 | D10: =DATEVALUE(TEXT(Raw_Data!D10, "YYYY-MM-DD")) -> 46028 | E10: =IF(ISBLANK(Raw_Data!E10), "", DATEVALUE(TEXT(Raw_Data!E10, "YYYY-MM-DD"))) -> 46034 | F10: =IF(C10="Metro", 2, IF(C10="Tier 2", 4, 6)) -> 6 | G10: =IF(E10="", "In-Transit", NETWORKDAYS(D10, E10)) -> 5 | H10: =IF(G10="In-Transit", "Pending", IF(G10>F10, "SLA BREACH", "ON TIME")) -> ON TIME | I10: =Raw_Data!F10 -> 2250 | J10: =IF(H10="SLA BREACH", I10 * 0.05, 0) -> 0
A11: =Raw_Data!A11 -> TRK100009 | B11: =TRIM(Raw_Data!B11) -> Delhivery | C11: =TRIM(Raw_Data!C11) -> Metro | D11: =DATEVALUE(TEXT(Raw_Data!D11, "YYYY-MM-DD")) -> 46075 | E11: =IF(ISBLANK(Raw_Data!E11), "", DATEVALUE(TEXT(Raw_Data!E11, "YYYY-MM-DD"))) -> 46078 | F11: =IF(C11="Metro", 2, IF(C11="Tier 2", 4, 6)) -> 2 | G11: =IF(E11="", "In-Transit", NETWORKDAYS(D11, E11)) -> 3 | H11: =IF(G11="In-Transit", "Pending", IF(G11>F11, "SLA BREACH", "ON TIME")) -> SLA BREACH | I11: =Raw_Data!F11 -> 6104 | J11: =IF(H11="SLA BREACH", I11 * 0.05, 0) -> 305.2
A12: =Raw_Data!A12 -> TRK100010 | B12: =TRIM(Raw_Data!B12) -> EcomExpress | C12: =TRIM(Raw_Data!C12) -> Tier 2 | D12: =DATEVALUE(TEXT(Raw_Data!D12, "YYYY-MM-DD")) -> 46079 | E12: =IF(ISBLANK(Raw_Data!E12), "", DATEVALUE(TEXT(Raw_Data!E12, "YYYY-MM-DD"))) -> 46083 | F12: =IF(C12="Metro", 2, IF(C12="Tier 2", 4, 6)) -> 4 | G12: =IF(E12="", "In-Transit", NETWORKDAYS(D12, E12)) -> 3 | H12: =IF(G12="In-Transit", "Pending", IF(G12>F12, "SLA BREACH", "ON TIME")) -> ON TIME | I12: =Raw_Data!F12 -> 2921 | J12: =IF(H12="SLA BREACH", I12 * 0.05, 0) -> 0
A13: =Raw_Data!A13 -> TRK100011 | B13: =TRIM(Raw_Data!B13) -> EcomExpress | C13: =TRIM(Raw_Data!C13) -> Metro | D13: =DATEVALUE(TEXT(Raw_Data!D13, "YYYY-MM-DD")) -> 46082 | E13: =IF(ISBLANK(Raw_Data!E13), "", DATEVALUE(TEXT(Raw_Data!E13, "YYYY-MM-DD"))) -> 46087 | F13: =IF(C13="Metro", 2, IF(C13="Tier 2", 4, 6)) -> 2 | G13: =IF(E13="", "In-Transit", NETWORKDAYS(D13, E13)) -> 5 | H13: =IF(G13="In-Transit", "Pending", IF(G13>F13, "SLA BREACH", "ON TIME")) -> SLA BREACH | I13: =Raw_Data!F13 -> 7619 | J13: =IF(H13="SLA BREACH", I13 * 0.05, 0) -> 380.95
... A1001: =Raw_Data!A1001 -> TRK100289 | B1001: =TRIM(Raw_Data!B1001) -> Delhivery | C1001: =TRIM(Raw_Data!C1001) -> Tier 2 | D1001: =DATEVALUE(TEXT(Raw_Data!D1001, "YYYY-MM-DD")) -> 46068 | E1001: =IF(ISBLANK(Raw_Data!E1001), "", DATEVALUE(TEXT(Raw_Data!E1001, "YYYY-MM-DD"))) -> 46072 | F1001: =IF(C1001="Metro", 2, IF(C1001="Tier 2", 4, 6)) -> 4 | G1001: =IF(E1001="", "In-Transit", NETWORKDAYS(D1001, E1001)) -> 4 | H1001: =IF(G1001="In-Transit", "Pending", IF(G1001>F1001, "SLA BREACH", "ON TIME")) -> ON TIME | I1001: =Raw_Data!F1001 -> 9511 | J1001: =IF(H1001="SLA BREACH", I1001 * 0.05, 0) -> 0

Sheet Executive_Dashboard
A1: Vendor SLA & Penalty Performance Dashboard
